<?xml version="1.0" encoding="utf-8"?>
<!-- This URDF was automatically created by SolidWorks to URDF Exporter! Originally created by Stephen Brawner (brawner@gmail.com) 
     Commit Version: 1.6.0-4-g7f85cfe  Build Version: 1.6.7995.38578
     For more information, please see http://wiki.ros.org/sw_urdf_exporter -->
<robot
  name="ROBOT1">
  <link
    name="base_link">
    <inertial>
      <origin
        xyz="0.116431751150278 -0.207178971089027 0.188316600433126"
        rpy="0 0 0" />
      <mass
        value="1.40070796326795" />
      <inertia
        ixx="0.00248542459104405"
        ixy="-9.02501417302497E-20"
        ixz="4.31279021540109E-20"
        iyy="0.0111146058983285"
        iyz="1.72286307219886E-19"
        izz="0.0132350008064984" />
    </inertial>
    <visual>
      <origin
        xyz="0 0 0"
        rpy="0 0 0" />
      <geometry>
        <mesh
          filename="package://ROBOT1/meshes/base_link.STL" />
      </geometry>
      <material
        name="">
        <color
          rgba="0.792156862745098 0.819607843137255 0.933333333333333 1" />
      </material>
    </visual>
    <collision>
      <origin
        xyz="0 0 0"
        rpy="0 0 0" />
      <geometry>
        <mesh
          filename="package://ROBOT1/meshes/base_link.STL" />
      </geometry>
    </collision>
  </link>
  <link
    name="coxa_fr">
    <inertial>
      <origin
        xyz="0.02 0.000754837272160719 0"
        rpy="0 0 0" />
      <mass
        value="0.062429203673205" />
      <inertia
        ixx="1.84677199387813E-05"
        ixy="2.59964096350411E-21"
        ixz="-1.3807824971985E-22"
        iyy="1.6647787646188E-05"
        iyz="-6.53877226174719E-22"
        izz="1.80684758723876E-05" />
    </inertial>
    <visual>
      <origin
        xyz="0 0 0"
        rpy="0 0 0" />
      <geometry>
        <mesh
          filename="package://ROBOT1/meshes/coxa_fr.STL" />
      </geometry>
      <material
        name="">
        <color
          rgba="0.792156862745098 0.819607843137255 0.933333333333333 1" />
      </material>
    </visual>
    <collision>
      <origin
        xyz="0 0 0"
        rpy="0 0 0" />
      <geometry>
        <mesh
          filename="package://ROBOT1/meshes/coxa_fr.STL" />
      </geometry>
    </collision>
  </link>
  <joint
    name="coxa_fr"
    type="continuous">
    <origin
      xyz="0.019861 -0.15718 0.18832"
      rpy="0 0 0" />
    <parent
      link="base_link" />
    <child
      link="coxa_fr" />
    <axis
      xyz="1 0 0" />
    <limit
      lower="0"
      upper="0"
      effort="0"
      velocity="0" />
  </joint>
  <link
    name="femur_fr">
    <inertial>
      <origin
        xyz="-0.0488437275890431 0 0.0064926417856572"
        rpy="0 0 0" />
      <mass
        value="0.0157853981633974" />
      <inertia
        ixx="7.75233261402973E-07"
        ixy="-3.26102594582921E-22"
        ixz="8.51912098405902E-07"
        iyy="1.37773588143548E-05"
        iyz="1.38245421068166E-22"
        izz="1.35744430299943E-05" />
    </inertial>
    <visual>
      <origin
        xyz="0 0 0"
        rpy="0 0 0" />
      <geometry>
        <mesh
          filename="package://ROBOT1/meshes/femur_fr.STL" />
      </geometry>
      <material
        name="">
        <color
          rgba="0.792156862745098 0.819607843137255 0.933333333333333 1" />
      </material>
    </visual>
    <collision>
      <origin
        xyz="0 0 0"
        rpy="0 0 0" />
      <geometry>
        <mesh
          filename="package://ROBOT1/meshes/femur_fr.STL" />
      </geometry>
    </collision>
  </link>
  <joint
    name="femur_fr"
    type="continuous">
    <origin
      xyz="0.02 0.03 0"
      rpy="-1.5708 -1.5708 0" />
    <parent
      link="coxa_fr" />
    <child
      link="femur_fr" />
    <axis
      xyz="0 0 1" />
    <limit
      lower="0"
      upper="0"
      effort="0"
      velocity="0" />
  </joint>
  <link
    name="tibia_fr">
    <inertial>
      <origin
        xyz="-0.0423007970042589 0 -0.005"
        rpy="0 0 0" />
      <mass
        value="0.0134292036732051" />
      <inertia
        ixx="3.83342553567574E-07"
        ixy="6.8124930770343E-23"
        ixz="1.74873797158678E-22"
        iyy="9.76478588361596E-06"
        iyz="-1.39562920708628E-22"
        izz="9.92430837596344E-06" />
    </inertial>
    <visual>
      <origin
        xyz="0 0 0"
        rpy="0 0 0" />
      <geometry>
        <mesh
          filename="package://ROBOT1/meshes/tibia_fr.STL" />
      </geometry>
      <material
        name="">
        <color
          rgba="0.792156862745098 0.819607843137255 0.933333333333333 1" />
      </material>
    </visual>
    <collision>
      <origin
        xyz="0 0 0"
        rpy="0 0 0" />
      <geometry>
        <mesh
          filename="package://ROBOT1/meshes/tibia_fr.STL" />
      </geometry>
    </collision>
  </link>
  <joint
    name="tibia_fr"
    type="continuous">
    <origin
      xyz="-0.085 0 0.02"
      rpy="3.1416 0 0" />
    <parent
      link="femur_fr" />
    <child
      link="tibia_fr" />
    <axis
      xyz="0 0 1" />
    <limit
      lower="0"
      upper="0"
      effort="0"
      velocity="0" />
  </joint>
  <link
    name="foot_fr">
    <inertial>
      <origin
        xyz="0 0.00579023503580695 1.38777878078145E-17"
        rpy="0 0 0" />
      <mass
        value="0.0017943951023932" />
      <inertia
        ixx="4.90753168728642E-08"
        ixy="1.0097419586829E-25"
        ixz="-5.34133682582635E-26"
        iyy="7.56508040957278E-08"
        iyz="-8.23009786527202E-25"
        izz="4.59503168728642E-08" />
    </inertial>
    <visual>
      <origin
        xyz="0 0 0"
        rpy="0 0 0" />
      <geometry>
        <mesh
          filename="package://ROBOT1/meshes/foot_fr.STL" />
      </geometry>
      <material
        name="">
        <color
          rgba="0.792156862745098 0.819607843137255 0.933333333333333 1" />
      </material>
    </visual>
    <collision>
      <origin
        xyz="0 0 0"
        rpy="0 0 0" />
      <geometry>
        <mesh
          filename="package://ROBOT1/meshes/foot_fr.STL" />
      </geometry>
    </collision>
  </link>
  <joint
    name="foot joint"
    type="fixed">
    <origin
      xyz="-0.10032 0 -0.005"
      rpy="0 0 -1.5708" />
    <parent
      link="tibia_fr" />
    <child
      link="foot_fr" />
    <axis
      xyz="0 0 0" />
  </joint>
  <link
    name="coxa_fl">
    <inertial>
      <origin
        xyz="0.02 0.000754837272160691 0"
        rpy="0 0 0" />
      <mass
        value="0.0624292036732051" />
      <inertia
        ixx="1.84677199387813E-05"
        ixy="-1.34804781449719E-21"
        ixz="7.25227782564925E-22"
        iyy="1.6647787646188E-05"
        iyz="1.56103809935542E-21"
        izz="1.80684758723876E-05" />
    </inertial>
    <visual>
      <origin
        xyz="0 0 0"
        rpy="0 0 0" />
      <geometry>
        <mesh
          filename="package://ROBOT1/meshes/coxa_fl.STL" />
      </geometry>
      <material
        name="">
        <color
          rgba="0.792156862745098 0.819607843137255 0.933333333333333 1" />
      </material>
    </visual>
    <collision>
      <origin
        xyz="0 0 0"
        rpy="0 0 0" />
      <geometry>
        <mesh
          filename="package://ROBOT1/meshes/coxa_fl.STL" />
      </geometry>
    </collision>
  </link>
  <joint
    name="coxa_fl"
    type="continuous">
    <origin
      xyz="0.019861116829854 -0.257178971089027 0.188316600433126"
      rpy="3.14159265358979 0 0" />
    <parent
      link="base_link" />
    <child
      link="coxa_fl" />
    <axis
      xyz="1 0 0" />
    <limit
      lower="0"
      upper="0"
      effort="0"
      velocity="0" />
  </joint>
  <link
    name="femur_fl">
    <inertial>
      <origin
        xyz="-0.0488437275890431 0 0.00649264178565717"
        rpy="0 0 0" />
      <mass
        value="0.0157853981633975" />
      <inertia
        ixx="7.75233261402972E-07"
        ixy="-2.66229483379994E-22"
        ixz="8.51912098405898E-07"
        iyy="1.37773588143548E-05"
        iyz="1.50833024394842E-22"
        izz="1.35744430299943E-05" />
    </inertial>
    <visual>
      <origin
        xyz="0 0 0"
        rpy="0 0 0" />
      <geometry>
        <mesh
          filename="package://ROBOT1/meshes/femur_fl.STL" />
      </geometry>
      <material
        name="">
        <color
          rgba="0.792156862745098 0.819607843137255 0.933333333333333 1" />
      </material>
    </visual>
    <collision>
      <origin
        xyz="0 0 0"
        rpy="0 0 0" />
      <geometry>
        <mesh
          filename="package://ROBOT1/meshes/femur_fl.STL" />
      </geometry>
    </collision>
  </link>
  <joint
    name="femur_fl"
    type="continuous">
    <origin
      xyz="0.02 0.03 0"
      rpy="-1.5708 1.5708 0" />
    <parent
      link="coxa_fl" />
    <child
      link="femur_fl" />
    <axis
      xyz="0 0 1" />
    <limit
      lower="0"
      upper="0"
      effort="0"
      velocity="0" />
  </joint>
  <link
    name="tibia_fl">
    <inertial>
      <origin
        xyz="-0.0423007970042589 0 0.005"
        rpy="0 0 0" />
      <mass
        value="0.0134292036732051" />
      <inertia
        ixx="3.83342553567575E-07"
        ixy="-2.14368580117323E-21"
        ixz="5.4762973838221E-23"
        iyy="9.76478588361596E-06"
        iyz="4.26013978711981E-23"
        izz="9.92430837596345E-06" />
    </inertial>
    <visual>
      <origin
        xyz="0 0 0"
        rpy="0 0 0" />
      <geometry>
        <mesh
          filename="package://ROBOT1/meshes/tibia_fl.STL" />
      </geometry>
      <material
        name="">
        <color
          rgba="0.792156862745098 0.819607843137255 0.933333333333333 1" />
      </material>
    </visual>
    <collision>
      <origin
        xyz="0 0 0"
        rpy="0 0 0" />
      <geometry>
        <mesh
          filename="package://ROBOT1/meshes/tibia_fl.STL" />
      </geometry>
    </collision>
  </link>
  <joint
    name="tibia_fl"
    type="continuous">
    <origin
      xyz="-0.085 0 0.02"
      rpy="0 0 0" />
    <parent
      link="femur_fl" />
    <child
      link="tibia_fl" />
    <axis
      xyz="0 0 1" />
    <limit
      lower="0"
      upper="0"
      effort="0"
      velocity="0" />
  </joint>
  <link
    name="foot_fl">
    <inertial>
      <origin
        xyz="0 0.00579023503580695 -5.55111512312578E-17"
        rpy="0 0 0" />
      <mass
        value="0.0017943951023932" />
      <inertia
        ixx="4.90753168728642E-08"
        ixy="-1.58822072698495E-23"
        ixz="6.61640046376351E-25"
        iyy="7.56508040957278E-08"
        iyz="-1.08742949959437E-26"
        izz="4.59503168728642E-08" />
    </inertial>
    <visual>
      <origin
        xyz="0 0 0"
        rpy="0 0 0" />
      <geometry>
        <mesh
          filename="package://ROBOT1/meshes/foot_fl.STL" />
      </geometry>
      <material
        name="">
        <color
          rgba="0.792156862745098 0.819607843137255 0.933333333333333 1" />
      </material>
    </visual>
    <collision>
      <origin
        xyz="0 0 0"
        rpy="0 0 0" />
      <geometry>
        <mesh
          filename="package://ROBOT1/meshes/foot_fl.STL" />
      </geometry>
    </collision>
  </link>
  <joint
    name="foot_fl"
    type="fixed">
    <origin
      xyz="-0.100321657493192 0 0.005"
      rpy="3.14159265358979 0 1.5707963267949" />
    <parent
      link="tibia_fl" />
    <child
      link="foot_fl" />
    <axis
      xyz="0 0 0" />
    <limit
      lower="0"
      upper="0"
      effort="0"
      velocity="0" />
  </joint>
  <link
    name="coxa_br">
    <inertial>
      <origin
        xyz="0.02 0.000754837272160747 -5.55111512312578E-17"
        rpy="0 0 0" />
      <mass
        value="0.0624292036732052" />
      <inertia
        ixx="1.84677199387814E-05"
        ixy="9.23454763566743E-21"
        ixz="-4.1881420550078E-22"
        iyy="1.66477876461881E-05"
        iyz="1.80035257789243E-21"
        izz="1.80684758723877E-05" />
    </inertial>
    <visual>
      <origin
        xyz="0 0 0"
        rpy="0 0 0" />
      <geometry>
        <mesh
          filename="package://ROBOT1/meshes/coxa_br.STL" />
      </geometry>
      <material
        name="">
        <color
          rgba="0.792156862745098 0.819607843137255 0.933333333333333 1" />
      </material>
    </visual>
    <collision>
      <origin
        xyz="0 0 0"
        rpy="0 0 0" />
      <geometry>
        <mesh
          filename="package://ROBOT1/meshes/coxa_br.STL" />
      </geometry>
    </collision>
  </link>
  <joint
    name="coxa_br"
    type="continuous">
    <origin
      xyz="0.16986 -0.15718 0.18832"
      rpy="0 0 0" />
    <parent
      link="base_link" />
    <child
      link="coxa_br" />
    <axis
      xyz="1 0 0" />
    <limit
      lower="0"
      upper="0"
      effort="0"
      velocity="0" />
  </joint>
  <link
    name="femur_br">
    <inertial>
      <origin
        xyz="-0.0488437275890431 0 0.00649264178565723"
        rpy="0 0 0" />
      <mass
        value="0.0157853981633975" />
      <inertia
        ixx="7.75233261402974E-07"
        ixy="1.43008841217722E-21"
        ixz="8.51912098405903E-07"
        iyy="1.37773588143548E-05"
        iyz="-2.35653862421307E-22"
        izz="1.35744430299943E-05" />
    </inertial>
    <visual>
      <origin
        xyz="0 0 0"
        rpy="0 0 0" />
      <geometry>
        <mesh
          filename="package://ROBOT1/meshes/femur_br.STL" />
      </geometry>
      <material
        name="">
        <color
          rgba="0.792156862745098 0.819607843137255 0.933333333333333 1" />
      </material>
    </visual>
    <collision>
      <origin
        xyz="0 0 0"
        rpy="0 0 0" />
      <geometry>
        <mesh
          filename="package://ROBOT1/meshes/femur_br.STL" />
      </geometry>
    </collision>
  </link>
  <joint
    name="femur_br"
    type="continuous">
    <origin
      xyz="0.02 0.03 0"
      rpy="-1.5708 -1.5708 0" />
    <parent
      link="coxa_br" />
    <child
      link="femur_br" />
    <axis
      xyz="0 0 1" />
    <limit
      lower="0"
      upper="0"
      effort="0"
      velocity="0" />
  </joint>
  <link
    name="tibia_br">
    <inertial>
      <origin
        xyz="-0.0423007970042589 0 0.00500000000000003"
        rpy="0 0 0" />
      <mass
        value="0.0134292036732051" />
      <inertia
        ixx="3.83342553567574E-07"
        ixy="3.75049844513447E-21"
        ixz="-2.08124615679892E-22"
        iyy="9.76478588361595E-06"
        iyz="-1.17058081558498E-23"
        izz="9.92430837596343E-06" />
    </inertial>
    <visual>
      <origin
        xyz="0 0 0"
        rpy="0 0 0" />
      <geometry>
        <mesh
          filename="package://ROBOT1/meshes/tibia_br.STL" />
      </geometry>
      <material
        name="">
        <color
          rgba="0.792156862745098 0.819607843137255 0.933333333333333 1" />
      </material>
    </visual>
    <collision>
      <origin
        xyz="0 0 0"
        rpy="0 0 0" />
      <geometry>
        <mesh
          filename="package://ROBOT1/meshes/tibia_br.STL" />
      </geometry>
    </collision>
  </link>
  <joint
    name="tibia_br"
    type="continuous">
    <origin
      xyz="-0.085 0 0.02"
      rpy="0 0 0" />
    <parent
      link="femur_br" />
    <child
      link="tibia_br" />
    <axis
      xyz="0 0 1" />
    <limit
      lower="0"
      upper="0"
      effort="0"
      velocity="0" />
  </joint>
  <link
    name="foot_br">
    <inertial>
      <origin
        xyz="0 0.00579023503580695 0"
        rpy="0 0 0" />
      <mass
        value="0.00179439510239319" />
      <inertia
        ixx="4.90753168728642E-08"
        ixy="3.22188395850702E-25"
        ixz="-5.34133682582648E-26"
        iyy="7.56508040957278E-08"
        iyz="-1.71453108836167E-24"
        izz="4.59503168728642E-08" />
    </inertial>
    <visual>
      <origin
        xyz="0 0 0"
        rpy="0 0 0" />
      <geometry>
        <mesh
          filename="package://ROBOT1/meshes/foot_br.STL" />
      </geometry>
      <material
        name="">
        <color
          rgba="0.792156862745098 0.819607843137255 0.933333333333333 1" />
      </material>
    </visual>
    <collision>
      <origin
        xyz="0 0 0"
        rpy="0 0 0" />
      <geometry>
        <mesh
          filename="package://ROBOT1/meshes/foot_br.STL" />
      </geometry>
    </collision>
  </link>
  <joint
    name="foot_br"
    type="fixed">
    <origin
      xyz="-0.100321657493192 0 0.00499999999999999"
      rpy="3.14159265358979 0 1.5707963267949" />
    <parent
      link="tibia_br" />
    <child
      link="foot_br" />
    <axis
      xyz="0 0 0" />
    <limit
      lower="0"
      upper="0"
      effort="0"
      velocity="0" />
  </joint>
  <link
    name="coxa_bl">
    <inertial>
      <origin
        xyz="0.02 0.000754837272160747 2.77555756156289E-17"
        rpy="0 0 0" />
      <mass
        value="0.0624292036732051" />
      <inertia
        ixx="1.84677199387814E-05"
        ixy="1.58361264310137E-21"
        ixz="-1.68015716286648E-21"
        iyy="1.6647787646188E-05"
        iyz="2.32934060494933E-21"
        izz="1.80684758723877E-05" />
    </inertial>
    <visual>
      <origin
        xyz="0 0 0"
        rpy="0 0 0" />
      <geometry>
        <mesh
          filename="package://ROBOT1/meshes/coxa_bl.STL" />
      </geometry>
      <material
        name="">
        <color
          rgba="0.792156862745098 0.819607843137255 0.933333333333333 1" />
      </material>
    </visual>
    <collision>
      <origin
        xyz="0 0 0"
        rpy="0 0 0" />
      <geometry>
        <mesh
          filename="package://ROBOT1/meshes/coxa_bl.STL" />
      </geometry>
    </collision>
  </link>
  <joint
    name="coxa_bl"
    type="continuous">
    <origin
      xyz="0.169861116829854 -0.257178971089027 0.188316600433126"
      rpy="-3.13765432050248 0 0" />
    <parent
      link="base_link" />
    <child
      link="coxa_bl" />
    <axis
      xyz="1 0 0" />
    <limit
      lower="0"
      upper="0"
      effort="0"
      velocity="0" />
  </joint>
  <link
    name="femur_bl">
    <inertial>
      <origin
        xyz="-0.0488437275890431 0 0.00649217647403771"
        rpy="0 0 0" />
      <mass
        value="0.0157853981633975" />
      <inertia
        ixx="7.75233261402974E-07"
        ixy="-8.14160537102829E-23"
        ixz="8.51912098405912E-07"
        iyy="1.37773588143548E-05"
        iyz="-7.91814676637872E-23"
        izz="1.35744430299943E-05" />
    </inertial>
    <visual>
      <origin
        xyz="0 0 0"
        rpy="0 0 0" />
      <geometry>
        <mesh
          filename="package://ROBOT1/meshes/femur_bl.STL" />
      </geometry>
      <material
        name="">
        <color
          rgba="0.792156862745098 0.819607843137255 0.933333333333333 1" />
      </material>
    </visual>
    <collision>
      <origin
        xyz="0 0 0"
        rpy="0 0 0" />
      <geometry>
        <mesh
          filename="package://ROBOT1/meshes/femur_bl.STL" />
      </geometry>
    </collision>
  </link>
  <joint
    name="femur_bl"
    type="continuous">
    <origin
      xyz="0.02 0.03 0"
      rpy="-1.5708 1.5708 0" />
    <parent
      link="coxa_bl" />
    <child
      link="femur_bl" />
    <axis
      xyz="0 0 1" />
    <limit
      lower="0"
      upper="0"
      effort="0"
      velocity="0" />
  </joint>
  <link
    name="tibia_bl">
    <inertial>
      <origin
        xyz="-0.0423007970042589 0 0.00499984489612687"
        rpy="0 0 0" />
      <mass
        value="0.0134292036732051" />
      <inertia
        ixx="3.83342553567574E-07"
        ixy="-3.63861712562797E-21"
        ixz="9.71771783627297E-21"
        iyy="9.76478588361595E-06"
        iyz="9.93976075638578E-24"
        izz="9.92430837596344E-06" />
    </inertial>
    <visual>
      <origin
        xyz="0 0 0"
        rpy="0 0 0" />
      <geometry>
        <mesh
          filename="package://ROBOT1/meshes/tibia_bl.STL" />
      </geometry>
      <material
        name="">
        <color
          rgba="0.792156862745098 0.819607843137255 0.933333333333333 1" />
      </material>
    </visual>
    <collision>
      <origin
        xyz="0 0 0"
        rpy="0 0 0" />
      <geometry>
        <mesh
          filename="package://ROBOT1/meshes/tibia_bl.STL" />
      </geometry>
    </collision>
  </link>
  <joint
    name="tibia_bl"
    type="continuous">
    <origin
      xyz="-0.0850000000000007 0 0.019999689792254"
      rpy="0 0 0" />
    <parent
      link="femur_bl" />
    <child
      link="tibia_bl" />
    <axis
      xyz="0 0 1" />
    <limit
      lower="0"
      upper="0"
      effort="0"
      velocity="0" />
  </joint>
  <link
    name="foot_bl">
    <inertial>
      <origin
        xyz="0 0.00579023503580695 5.55111512312578E-17"
        rpy="0 0 0" />
      <mass
        value="0.00179439510239319" />
      <inertia
        ixx="4.90753168728643E-08"
        ixy="4.26110048274861E-25"
        ixz="-1.91332358916639E-25"
        iyy="7.56508040957278E-08"
        iyz="-4.26902744259789E-23"
        izz="4.59503168728642E-08" />
    </inertial>
    <visual>
      <origin
        xyz="0 0 0"
        rpy="0 0 0" />
      <geometry>
        <mesh
          filename="package://ROBOT1/meshes/foot_bl.STL" />
      </geometry>
      <material
        name="">
        <color
          rgba="0.792156862745098 0.819607843137255 0.933333333333333 1" />
      </material>
    </visual>
    <collision>
      <origin
        xyz="0 0 0"
        rpy="0 0 0" />
      <geometry>
        <mesh
          filename="package://ROBOT1/meshes/foot_bl.STL" />
      </geometry>
    </collision>
  </link>
  <joint
    name="foot_bl"
    type="fixed">
    <origin
      xyz="-0.100321657493192 0 0.00499984489612731"
      rpy="0 0 -1.5707963267949" />
    <parent
      link="tibia_bl" />
    <child
      link="foot_bl" />
    <axis
      xyz="0 0 0" />
  </joint>
</robot>